nohup: ignoring input
================================================================================
load pg_denormalized
================================================================================
================================================================================
load pg_normalized_batch
================================================================================
2025-05-06 10:04:16.819559 /data/tweets/geoTwitter21-01-01.zip
2025-05-06 10:04:32.520501 insert_tweets i= 0
Traceback (most recent call last):
  File "/data/users_bigdata/agaglan2/twitter_postgres_indexes/load_tweets_batch.py", line 432, in <module>
    insert_tweets(connection,tweets,args.batch_size)
  File "/data/users_bigdata/agaglan2/twitter_postgres_indexes/load_tweets_batch.py", line 149, in insert_tweets
    _insert_tweets(connection, tweet_batch)
  File "/data/users_bigdata/agaglan2/twitter_postgres_indexes/load_tweets_batch.py", line 368, in _insert_tweets
    with connection.begin() as trans:
         ^^^^^^^^^^^^^^^^^^
  File "/data/users_bigdata/agaglan2/twitter_postgres_indexes/venv/lib/python3.12/site-packages/sqlalchemy/engine/base.py", line 862, in begin
    raise exc.InvalidRequestError(
sqlalchemy.exc.InvalidRequestError: This connection has already initialized a SQLAlchemy Transaction() object via begin() or autobegin; can't call begin() here unless rollback() or commit() is called first.
2025-05-06 10:04:16.824008 /data/tweets/geoTwitter21-01-05.zip
2025-05-06 10:04:33.046099 insert_tweets i= 0
Traceback (most recent call last):
  File "/data/users_bigdata/agaglan2/twitter_postgres_indexes/load_tweets_batch.py", line 432, in <module>
    insert_tweets(connection,tweets,args.batch_size)
  File "/data/users_bigdata/agaglan2/twitter_postgres_indexes/load_tweets_batch.py", line 149, in insert_tweets
    _insert_tweets(connection, tweet_batch)
  File "/data/users_bigdata/agaglan2/twitter_postgres_indexes/load_tweets_batch.py", line 368, in _insert_tweets
    with connection.begin() as trans:
         ^^^^^^^^^^^^^^^^^^
  File "/data/users_bigdata/agaglan2/twitter_postgres_indexes/venv/lib/python3.12/site-packages/sqlalchemy/engine/base.py", line 862, in begin
    raise exc.InvalidRequestError(
sqlalchemy.exc.InvalidRequestError: This connection has already initialized a SQLAlchemy Transaction() object via begin() or autobegin; can't call begin() here unless rollback() or commit() is called first.
2025-05-06 10:04:16.803665 /data/tweets/geoTwitter21-01-02.zip
2025-05-06 10:04:33.746550 insert_tweets i= 0
Traceback (most recent call last):
  File "/data/users_bigdata/agaglan2/twitter_postgres_indexes/load_tweets_batch.py", line 432, in <module>
    insert_tweets(connection,tweets,args.batch_size)
  File "/data/users_bigdata/agaglan2/twitter_postgres_indexes/load_tweets_batch.py", line 149, in insert_tweets
    _insert_tweets(connection, tweet_batch)
  File "/data/users_bigdata/agaglan2/twitter_postgres_indexes/load_tweets_batch.py", line 368, in _insert_tweets
    with connection.begin() as trans:
         ^^^^^^^^^^^^^^^^^^
  File "/data/users_bigdata/agaglan2/twitter_postgres_indexes/venv/lib/python3.12/site-packages/sqlalchemy/engine/base.py", line 862, in begin
    raise exc.InvalidRequestError(
sqlalchemy.exc.InvalidRequestError: This connection has already initialized a SQLAlchemy Transaction() object via begin() or autobegin; can't call begin() here unless rollback() or commit() is called first.
2025-05-06 10:04:16.843559 /data/tweets/geoTwitter21-01-03.zip
2025-05-06 10:04:33.802124 insert_tweets i= 0
Traceback (most recent call last):
  File "/data/users_bigdata/agaglan2/twitter_postgres_indexes/load_tweets_batch.py", line 432, in <module>
    insert_tweets(connection,tweets,args.batch_size)
  File "/data/users_bigdata/agaglan2/twitter_postgres_indexes/load_tweets_batch.py", line 149, in insert_tweets
    _insert_tweets(connection, tweet_batch)
  File "/data/users_bigdata/agaglan2/twitter_postgres_indexes/load_tweets_batch.py", line 368, in _insert_tweets
    with connection.begin() as trans:
         ^^^^^^^^^^^^^^^^^^
  File "/data/users_bigdata/agaglan2/twitter_postgres_indexes/venv/lib/python3.12/site-packages/sqlalchemy/engine/base.py", line 862, in begin
    raise exc.InvalidRequestError(
sqlalchemy.exc.InvalidRequestError: This connection has already initialized a SQLAlchemy Transaction() object via begin() or autobegin; can't call begin() here unless rollback() or commit() is called first.
2025-05-06 10:04:16.803671 /data/tweets/geoTwitter21-01-09.zip
2025-05-06 10:04:34.074685 insert_tweets i= 0
Traceback (most recent call last):
  File "/data/users_bigdata/agaglan2/twitter_postgres_indexes/load_tweets_batch.py", line 432, in <module>
    insert_tweets(connection,tweets,args.batch_size)
  File "/data/users_bigdata/agaglan2/twitter_postgres_indexes/load_tweets_batch.py", line 149, in insert_tweets
    _insert_tweets(connection, tweet_batch)
  File "/data/users_bigdata/agaglan2/twitter_postgres_indexes/load_tweets_batch.py", line 368, in _insert_tweets
    with connection.begin() as trans:
         ^^^^^^^^^^^^^^^^^^
  File "/data/users_bigdata/agaglan2/twitter_postgres_indexes/venv/lib/python3.12/site-packages/sqlalchemy/engine/base.py", line 862, in begin
    raise exc.InvalidRequestError(
sqlalchemy.exc.InvalidRequestError: This connection has already initialized a SQLAlchemy Transaction() object via begin() or autobegin; can't call begin() here unless rollback() or commit() is called first.
2025-05-06 10:04:16.850160 /data/tweets/geoTwitter21-01-04.zip
2025-05-06 10:04:34.643218 insert_tweets i= 0
Traceback (most recent call last):
  File "/data/users_bigdata/agaglan2/twitter_postgres_indexes/load_tweets_batch.py", line 432, in <module>
    insert_tweets(connection,tweets,args.batch_size)
  File "/data/users_bigdata/agaglan2/twitter_postgres_indexes/load_tweets_batch.py", line 149, in insert_tweets
    _insert_tweets(connection, tweet_batch)
  File "/data/users_bigdata/agaglan2/twitter_postgres_indexes/load_tweets_batch.py", line 368, in _insert_tweets
    with connection.begin() as trans:
         ^^^^^^^^^^^^^^^^^^
  File "/data/users_bigdata/agaglan2/twitter_postgres_indexes/venv/lib/python3.12/site-packages/sqlalchemy/engine/base.py", line 862, in begin
    raise exc.InvalidRequestError(
sqlalchemy.exc.InvalidRequestError: This connection has already initialized a SQLAlchemy Transaction() object via begin() or autobegin; can't call begin() here unless rollback() or commit() is called first.
2025-05-06 10:04:16.834514 /data/tweets/geoTwitter21-01-07.zip
2025-05-06 10:04:35.361643 insert_tweets i= 0
Traceback (most recent call last):
  File "/data/users_bigdata/agaglan2/twitter_postgres_indexes/load_tweets_batch.py", line 432, in <module>
    insert_tweets(connection,tweets,args.batch_size)
  File "/data/users_bigdata/agaglan2/twitter_postgres_indexes/load_tweets_batch.py", line 149, in insert_tweets
    _insert_tweets(connection, tweet_batch)
  File "/data/users_bigdata/agaglan2/twitter_postgres_indexes/load_tweets_batch.py", line 368, in _insert_tweets
    with connection.begin() as trans:
         ^^^^^^^^^^^^^^^^^^
  File "/data/users_bigdata/agaglan2/twitter_postgres_indexes/venv/lib/python3.12/site-packages/sqlalchemy/engine/base.py", line 862, in begin
    raise exc.InvalidRequestError(
sqlalchemy.exc.InvalidRequestError: This connection has already initialized a SQLAlchemy Transaction() object via begin() or autobegin; can't call begin() here unless rollback() or commit() is called first.
2025-05-06 10:04:16.875865 /data/tweets/geoTwitter21-01-08.zip
2025-05-06 10:04:35.642368 insert_tweets i= 0
Traceback (most recent call last):
  File "/data/users_bigdata/agaglan2/twitter_postgres_indexes/load_tweets_batch.py", line 432, in <module>
    insert_tweets(connection,tweets,args.batch_size)
  File "/data/users_bigdata/agaglan2/twitter_postgres_indexes/load_tweets_batch.py", line 149, in insert_tweets
    _insert_tweets(connection, tweet_batch)
  File "/data/users_bigdata/agaglan2/twitter_postgres_indexes/load_tweets_batch.py", line 368, in _insert_tweets
    with connection.begin() as trans:
         ^^^^^^^^^^^^^^^^^^
  File "/data/users_bigdata/agaglan2/twitter_postgres_indexes/venv/lib/python3.12/site-packages/sqlalchemy/engine/base.py", line 862, in begin
    raise exc.InvalidRequestError(
sqlalchemy.exc.InvalidRequestError: This connection has already initialized a SQLAlchemy Transaction() object via begin() or autobegin; can't call begin() here unless rollback() or commit() is called first.
2025-05-06 10:04:16.895017 /data/tweets/geoTwitter21-01-10.zip
2025-05-06 10:04:35.787103 insert_tweets i= 0
Traceback (most recent call last):
  File "/data/users_bigdata/agaglan2/twitter_postgres_indexes/load_tweets_batch.py", line 432, in <module>
    insert_tweets(connection,tweets,args.batch_size)
  File "/data/users_bigdata/agaglan2/twitter_postgres_indexes/load_tweets_batch.py", line 149, in insert_tweets
    _insert_tweets(connection, tweet_batch)
  File "/data/users_bigdata/agaglan2/twitter_postgres_indexes/load_tweets_batch.py", line 368, in _insert_tweets
    with connection.begin() as trans:
         ^^^^^^^^^^^^^^^^^^
  File "/data/users_bigdata/agaglan2/twitter_postgres_indexes/venv/lib/python3.12/site-packages/sqlalchemy/engine/base.py", line 862, in begin
    raise exc.InvalidRequestError(
sqlalchemy.exc.InvalidRequestError: This connection has already initialized a SQLAlchemy Transaction() object via begin() or autobegin; can't call begin() here unless rollback() or commit() is called first.
2025-05-06 10:04:16.855775 /data/tweets/geoTwitter21-01-06.zip
2025-05-06 10:04:38.570522 insert_tweets i= 0
Traceback (most recent call last):
  File "/data/users_bigdata/agaglan2/twitter_postgres_indexes/load_tweets_batch.py", line 432, in <module>
    insert_tweets(connection,tweets,args.batch_size)
  File "/data/users_bigdata/agaglan2/twitter_postgres_indexes/load_tweets_batch.py", line 149, in insert_tweets
    _insert_tweets(connection, tweet_batch)
  File "/data/users_bigdata/agaglan2/twitter_postgres_indexes/load_tweets_batch.py", line 368, in _insert_tweets
    with connection.begin() as trans:
         ^^^^^^^^^^^^^^^^^^
  File "/data/users_bigdata/agaglan2/twitter_postgres_indexes/venv/lib/python3.12/site-packages/sqlalchemy/engine/base.py", line 862, in begin
    raise exc.InvalidRequestError(
sqlalchemy.exc.InvalidRequestError: This connection has already initialized a SQLAlchemy Transaction() object via begin() or autobegin; can't call begin() here unless rollback() or commit() is called first.
Command exited with non-zero status 10
212.93user 18.30system 0:34.05elapsed 679%CPU (0avgtext+0avgdata 2677760maxresident)k
1564512inputs+4280outputs (76major+7429041minor)pagefaults 0swaps
